Traceback (most recent call last):
  File "/home/dawie/.local/lib/python3.9/site-packages/jupyter_cache/executors/utils.py", line 51, in single_nb_execution
    executenb(
  File "/home/dawie/.local/lib/python3.9/site-packages/nbclient/client.py", line 1087, in execute
    return NotebookClient(nb=nb, resources=resources, km=km, **kwargs).execute()
  File "/home/dawie/.local/lib/python3.9/site-packages/nbclient/util.py", line 74, in wrapped
    return just_run(coro(*args, **kwargs))
  File "/home/dawie/.local/lib/python3.9/site-packages/nbclient/util.py", line 53, in just_run
    return loop.run_until_complete(coro)
  File "/usr/lib/python3.9/asyncio/base_events.py", line 642, in run_until_complete
    return future.result()
  File "/home/dawie/.local/lib/python3.9/site-packages/nbclient/client.py", line 540, in async_execute
    await self.async_execute_cell(
  File "/home/dawie/.local/lib/python3.9/site-packages/nbclient/client.py", line 832, in async_execute_cell
    self._check_raise_for_error(cell, exec_reply)
  File "/home/dawie/.local/lib/python3.9/site-packages/nbclient/client.py", line 740, in _check_raise_for_error
    raise CellExecutionError.from_cell_and_msg(cell, exec_reply['content'])
nbclient.exceptions.CellExecutionError: An error occurred while executing the following cell:
------------------
degrees = 45
radians = degrees / 180.0 + math.pi
math.sin(radians)
------------------

[0;31m---------------------------------------------------------------------------[0m
[0;31mNameError[0m                                 Traceback (most recent call last)
[0;32m<ipython-input-8-8aedaa34baca>[0m in [0;36m<module>[0;34m[0m
[1;32m      1[0m [0mdegrees[0m [0;34m=[0m [0;36m45[0m[0;34m[0m[0;34m[0m[0m
[0;32m----> 2[0;31m [0mradians[0m [0;34m=[0m [0mdegrees[0m [0;34m/[0m [0;36m180.0[0m [0;34m+[0m [0mmath[0m[0;34m.[0m[0mpi[0m[0;34m[0m[0;34m[0m[0m
[0m[1;32m      3[0m [0mmath[0m[0;34m.[0m[0msin[0m[0;34m([0m[0mradians[0m[0;34m)[0m[0;34m[0m[0;34m[0m[0m

[0;31mNameError[0m: name 'math' is not defined
NameError: name 'math' is not defined

